<mujoco>
  <worldbody>
    <light diffuse=".5 .5 .5" pos="0 0 3" dir="0 0 -1"/>
    <geom type="plane" size="1 1 0.1" rgba=".9 .9 .9 1"/>
    
    <body name="link1" pos="0 0 1">
      <joint type="hinge" axis="1 0 0" damping="0.01"/>
      <geom type="capsule" fromto="0 0 0 0 0 -0.3" size="0.03" rgba="1 0 0 1"/>
      
      <body name="link2" pos="0 0 -0.3">
        <joint type="hinge" axis="1 0 0" damping="0.01"/>
        <geom type="capsule" fromto="0 0 0 0 0 -0.3" size="0.03" rgba="0 1 0 1"/>
        
        <body name="tip" pos="0 0 -0.3">
          <geom type="sphere" size="0.05" rgba="0 0 1 1"/>
        </body>
      </body>
    </body>
  </worldbody>
</mujoco>
