<mujoco model="bins_arena">
  <compiler angle="radian" meshdir="meshes/" texturedir="textures/"/>

  <default>
    <default class="env:main"/>
    <default class="robot_0:main">
      <default class="robot_0:so101">
        <joint armature="0.005" damping="1" frictionloss="0.1"/>
        <general biastype="affine" gainprm="50" biasprm="0 -50"/>
        <default class="robot_0:visual">
          <geom type="mesh" contype="0" conaffinity="0" group="1"/>
        </default>
        <default class="robot_0:collision">
          <geom group="3"/>
          <default class="robot_0:pad">
            <geom type="box" condim="4" priority="1" friction="4 4 4" solref="0.0008" solimp="0.99 0.99" margin="0.001"/>
          </default>
        </default>
      </default>
      <default class="robot_0:sts3215">
        <joint armature="0.028" damping="0.6" frictionloss="0.052"/>
        <geom contype="0" conaffinity="0"/>
        <general biastype="affine" gainprm="17.8" biasprm="0 -17.8"/>
      </default>
    </default>
    <default class="mount_0:main"/>
  </default>

  <asset>
    <texture type="skybox" colorspace="auto" builtin="gradient" rgb1="0.9 0.9 1" rgb2="0.2 0.3 0.4" width="256" height="1536"/>
    <texture type="cube" colorspace="auto" name="texplane" builtin="gradient" rgb1="0.7 0.7 0.7" width="256" height="1536"/>
    <texture type="cube" colorspace="linear" name="tex-steel-brushed" file="steel-brushed.png"/>
    <texture type="2d" colorspace="linear" name="tex-light-wood" file="light-wood.png"/>
    <texture type="2d" colorspace="linear" name="tex-dark-wood" file="dark-wood.png"/>
    <texture type="2d" colorspace="linear" name="env:cube_tex" file="cube.png"/>
    <texture type="2d" colorspace="linear" name="env:cylinder_tex" file="cylinder.png"/>
    <texture type="2d" colorspace="linear" name="env:sphere_tex" file="sphere.png"/>
    <texture type="2d" colorspace="linear" name="env:capsule_tex" file="capsule.png"/>
    <texture type="2d" colorspace="linear" name="env:rectangle_tex" file="rectangle.png"/>
    <material name="floorplane" texture="texplane" texuniform="true" texrepeat="2 2" specular="0" shininess="0" reflectance="0.01"/>
    <material name="table_legs_metal" texture="tex-steel-brushed" shininess="0.8" reflectance="0.8"/>
    <material name="light-wood" texture="tex-light-wood" texuniform="true" texrepeat="15 15"/>
    <material name="dark-wood" texture="tex-dark-wood" texuniform="true" texrepeat="5 5"/>
    <material name="env:cube_mat" texture="env:cube_tex"/>
    <material name="env:cylinder_mat" texture="env:cylinder_tex"/>
    <material name="env:sphere_mat" texture="env:sphere_tex"/>
    <material name="env:capsule_mat" texture="env:capsule_tex"/>
    <material name="env:rectangle_mat" texture="env:rectangle_tex"/>
    <material name="robot_0:base_motor_holder_so101_v1_material" rgba="1 0.82 0.12 1"/>
    <material name="robot_0:base_so101_v2_material" rgba="1 0.82 0.12 1"/>
    <material name="robot_0:sts3215_03a_v1_material" rgba="0.1 0.1 0.1 1"/>
    <material name="robot_0:waveshare_mounting_plate_so101_v2_material" rgba="1 0.82 0.12 1"/>
    <material name="robot_0:motor_holder_so101_base_v1_material" rgba="1 0.82 0.12 1"/>
    <material name="robot_0:rotation_pitch_so101_v1_material" rgba="1 0.82 0.12 1"/>
    <material name="robot_0:upper_arm_so101_v1_material" rgba="1 0.82 0.12 1"/>
    <material name="robot_0:under_arm_so101_v1_material" rgba="1 0.82 0.12 1"/>
    <material name="robot_0:motor_holder_so101_wrist_v1_material" rgba="1 0.82 0.12 1"/>
    <material name="robot_0:sts3215_03a_no_horn_v1_material" rgba="0.1 0.1 0.1 1"/>
    <material name="robot_0:wrist_roll_pitch_so101_v2_material" rgba="1 0.82 0.12 1"/>
    <material name="robot_0:wrist_roll_follower_so101_v1_material" rgba="1 0.82 0.12 1"/>
    <material name="robot_0:moving_jaw_so101_v1_material" rgba="1 0.82 0.12 1"/>
    <mesh name="robot_0:waveshare_mounting_plate_so101_v2" file="so101/waveshare_mounting_plate_so101_v2.stl"/>
    <mesh name="robot_0:sts3215_03a_v1" file="so101/sts3215_03a_v1.stl"/>
    <mesh name="robot_0:motor_holder_so101_base_v1" file="so101/motor_holder_so101_base_v1.stl"/>
    <mesh name="robot_0:wrist_roll_follower_so101_v1" file="so101/wrist_roll_follower_so101_v1.stl"/>
    <mesh name="robot_0:moving_jaw_so101_v1" file="so101/moving_jaw_so101_v1.stl"/>
    <mesh name="robot_0:base_motor_holder_so101_v1" file="so101/base_motor_holder_so101_v1.stl"/>
    <mesh name="robot_0:upper_arm_so101_v1" file="so101/upper_arm_so101_v1.stl"/>
    <mesh name="robot_0:wrist_roll_pitch_so101_v2" file="so101/wrist_roll_pitch_so101_v2.stl"/>
    <mesh name="robot_0:under_arm_so101_v1" file="so101/under_arm_so101_v1.stl"/>
    <mesh name="robot_0:rotation_pitch_so101_v1" file="so101/rotation_pitch_so101_v1.stl"/>
    <mesh name="robot_0:motor_holder_so101_wrist_v1" file="so101/motor_holder_so101_wrist_v1.stl"/>
    <mesh name="robot_0:sts3215_03a_no_horn_v1" file="so101/sts3215_03a_no_horn_v1.stl"/>
    <mesh name="robot_0:base_so101_v2" file="so101/base_so101_v2.stl"/>
    <mesh name="mount_0:pedestal" file="rethink_mount/pedestal.stl" scale="0.6 0.6 0.6"/>
  </asset>

  <worldbody>
    <geom name="floor" size="3 3 0.125" type="plane" conaffinity="15" group="1" material="floorplane"/>
    <camera name="frontview" pos="1.6 0 1.45" quat="0.560842 0.430646 0.430646 0.560842"/>
    <camera name="birdview" pos="-0.2 0 3" quat="0.707107 0 0 0.707107"/>
    <camera name="agentview" pos="1 0 1.75" quat="0.653098 0.271041 0.271041 0.653098"/>
    <light pos="1 1 1.5" dir="-0.19245 -0.19245 -0.96225" type="directional" castshadow="false"/>
    <body name="bin1" pos="0.06 -0.15 0.48">
      <geom size="0.12 0.165 0.012" type="box" contype="2" conaffinity="15"/>
      <geom size="0.12 0.165 0.012" type="box" contype="0" conaffinity="0" group="1" material="light-wood"/>
      <geom size="0.12 0.165 0.006" pos="0 0 -0.018" type="box" contype="2" conaffinity="15"/>
      <geom size="0.12 0.165 0.006" pos="0 0 -0.018" type="box" contype="0" conaffinity="0" group="1" material="light-wood"/>
      <geom size="0.126 0.006 0.03" pos="0 0.165 0.03" type="box" contype="4" conaffinity="15" rgba="0 0 1 1"/>
      <geom size="0.126 0.006 0.03" pos="0 0.165 0.03" type="box" contype="0" conaffinity="0" group="1" material="light-wood"/>
      <geom size="0.126 0.006 0.03" pos="0 -0.165 0.03" type="box" contype="4" conaffinity="15" rgba="0 0 1 1"/>
      <geom size="0.126 0.006 0.03" pos="0 -0.165 0.03" type="box" contype="0" conaffinity="0" group="1" material="light-wood"/>
      <geom size="0.006 0.165 0.03" pos="0.12 0 0.03" type="box" contype="4" conaffinity="15" rgba="0 0 1 1"/>
      <geom size="0.006 0.165 0.03" pos="0.12 0 0.03" type="box" contype="0" conaffinity="0" group="1" material="light-wood"/>
      <geom size="0.006 0.165 0.03" pos="-0.12 0 0.03" type="box" contype="4" conaffinity="15" rgba="0 0 1 1"/>
      <geom size="0.006 0.165 0.03" pos="-0.12 0 0.03" type="box" contype="0" conaffinity="0" group="1" material="light-wood"/>
      <geom name="bin1_leg1_visual" size="0.006 0.24" pos="0.09 0.12 -0.24" type="cylinder" contype="0" conaffinity="0" group="1" material="table_legs_metal"/>
      <geom name="bin1_leg2_visual" size="0.006 0.24" pos="-0.09 0.12 -0.24" type="cylinder" contype="0" conaffinity="0" group="1" material="table_legs_metal"/>
      <geom name="bin1_leg3_visual" size="0.006 0.24" pos="-0.09 -0.12 -0.24" type="cylinder" contype="0" conaffinity="0" group="1" material="table_legs_metal"/>
      <geom name="bin1_leg4_visual" size="0.006 0.24" pos="0.09 -0.12 -0.24" type="cylinder" contype="0" conaffinity="0" group="1" material="table_legs_metal"/>
    </body>
    <body name="bin2" pos="0.06 0.18 0.48">
      <geom size="0.12 0.15 0.012" type="box" contype="2" conaffinity="15"/>
      <geom size="0.12 0.15 0.012" type="box" contype="0" conaffinity="0" group="1" material="dark-wood"/>
      <geom size="0.12 0.15 0.006" pos="0 0 -0.018" type="box" contype="2" conaffinity="15"/>
      <geom size="0.12 0.15 0.006" pos="0 0 -0.018" type="box" contype="0" conaffinity="0" group="1" material="dark-wood"/>
      <geom size="0.126 0.006 0.03" pos="0 0.15 0.03" type="box" contype="4" conaffinity="15" rgba="0 0 1 1"/>
      <geom size="0.126 0.006 0.03" pos="0 0.15 0.03" type="box" contype="0" conaffinity="0" group="1" material="dark-wood"/>
      <geom size="0.126 0.006 0.03" pos="0 -0.15 0.03" type="box" contype="4" conaffinity="15" rgba="0 0 1 1"/>
      <geom size="0.126 0.006 0.03" pos="0 -0.15 0.03" type="box" contype="0" conaffinity="0" group="1" material="dark-wood"/>
      <geom size="0.006 0.15 0.03" pos="0.12 0 0.03" type="box" contype="4" conaffinity="15" rgba="0 0 1 1"/>
      <geom size="0.006 0.15 0.03" pos="0.12 0 0.03" type="box" contype="0" conaffinity="0" group="1" material="dark-wood"/>
      <geom size="0.006 0.15 0.03" pos="-0.12 0 0.03" type="box" contype="4" conaffinity="15" rgba="0 0 1 1"/>
      <geom size="0.006 0.15 0.03" pos="-0.12 0 0.03" type="box" contype="0" conaffinity="0" group="1" material="dark-wood"/>
      <geom name="bin2_leg1_visual" size="0.006 0.24" pos="0.09 0.12 -0.24" type="cylinder" contype="0" conaffinity="0" group="1" material="table_legs_metal"/>
      <geom name="bin2_leg2_visual" size="0.006 0.24" pos="-0.09 0.12 -0.24" type="cylinder" contype="0" conaffinity="0" group="1" material="table_legs_metal"/>
      <geom name="bin2_leg3_visual" size="0.006 0.24" pos="-0.09 -0.12 -0.24" type="cylinder" contype="0" conaffinity="0" group="1" material="table_legs_metal"/>
      <geom name="bin2_leg4_visual" size="0.006 0.24" pos="0.09 -0.12 -0.24" type="cylinder" contype="0" conaffinity="0" group="1" material="table_legs_metal"/>
    </body>
    <body name="env:cube_target" pos="-0.45 0 0.12">
      <joint name="env:cube_target_joint" type="free"/>
      <geom size="0.006 0.006 0.006" type="box" conaffinity="15" mass="0.01" rgba="0 0 0 0"/>
      <geom name="env:cube_target_geom" size="0.018 0.018 0.003" type="box" contype="0" conaffinity="0" rgba="0 0 0 0"/>
      <geom name="env:cube_target_floor" size="0.054 0.066 0.0012" pos="0 0 0.0012" type="box" material="env:cube_mat" rgba="1 1 1 1"/>
      <geom name="env:cube_target_wall_north" size="0.054 0.0006 0.024" pos="0 0.066 0.012" type="box" material="env:cube_mat" rgba="1 1 1 1"/>
      <geom name="env:cube_target_wall_south" size="0.054 0.0006 0.024" pos="0 -0.066 0.012" type="box" material="env:cube_mat" rgba="1 1 1 1"/>
      <geom name="env:cube_target_wall_east" size="0.0006 0.066 0.024" pos="0.054 0 0.012" type="box" material="env:cube_mat" rgba="1 1 1 1"/>
      <geom name="env:cube_target_wall_west" size="0.0006 0.066 0.024" pos="-0.054 0 0.012" type="box" material="env:cube_mat" rgba="1 1 1 1"/>
    </body>
    <body name="env:cylinder_target">
      <joint name="env:cylinder_target_joint" type="free"/>
      <geom size="0.006 0.006 0.006" type="box" conaffinity="15" mass="0.01" rgba="0 0 0 0"/>
      <geom name="env:cylinder_target_geom" size="0.018 0.018 0.003" type="box" contype="0" conaffinity="0" rgba="0 0 0 0"/>
      <geom name="env:cylinder_target_floor" size="0.054 0.066 0.0012" pos="0 0 0.0012" type="box" material="env:cylinder_mat" rgba="1 1 1 1"/>
      <geom name="env:cylinder_target_wall_north" size="0.054 0.0006 0.024" pos="0 0.066 0.012" type="box" material="env:cylinder_mat" rgba="1 1 1 1"/>
      <geom name="env:cylinder_target_wall_south" size="0.054 0.0006 0.024" pos="0 -0.066 0.012" type="box" material="env:cylinder_mat" rgba="1 1 1 1"/>
      <geom name="env:cylinder_target_wall_east" size="0.0006 0.066 0.024" pos="0.054 0 0.012" type="box" material="env:cylinder_mat" rgba="1 1 1 1"/>
      <geom name="env:cylinder_target_wall_west" size="0.0006 0.066 0.024" pos="-0.054 0 0.012" type="box" material="env:cylinder_mat" rgba="1 1 1 1"/>
    </body>
    <body name="env:sphere_target" pos="0.45 0 0.12">
      <joint name="env:sphere_target_joint" type="free"/>
      <geom size="0.006 0.006 0.006" type="box" conaffinity="15" mass="0.01" rgba="0 0 0 0"/>
      <geom name="env:sphere_target_geom" size="0.018 0.018 0.003" type="box" contype="0" conaffinity="0" rgba="0 0 0 0"/>
      <geom name="env:sphere_target_floor" size="0.054 0.066 0.0012" pos="0 0 0.0012" type="box" material="env:sphere_mat" rgba="1 1 1 1"/>
      <geom name="env:sphere_target_wall_north" size="0.054 0.0006 0.024" pos="0 0.066 0.012" type="box" material="env:sphere_mat" rgba="1 1 1 1"/>
      <geom name="env:sphere_target_wall_south" size="0.054 0.0006 0.024" pos="0 -0.066 0.012" type="box" material="env:sphere_mat" rgba="1 1 1 1"/>
      <geom name="env:sphere_target_wall_east" size="0.0006 0.066 0.024" pos="0.054 0 0.012" type="box" material="env:sphere_mat" rgba="1 1 1 1"/>
      <geom name="env:sphere_target_wall_west" size="0.0006 0.066 0.024" pos="-0.054 0 0.012" type="box" material="env:sphere_mat" rgba="1 1 1 1"/>
    </body>
    <body name="env:capsule_target" pos="0.12 -0.12 0.12">
      <joint name="env:capsule_target_joint" type="free"/>
      <geom size="0.006 0.006 0.006" type="box" conaffinity="15" mass="0.01" rgba="0 0 0 0"/>
      <geom name="env:capsule_target_geom" size="0.018 0.018 0.003" type="box" contype="0" conaffinity="0" rgba="0 0 0 0"/>
      <geom name="env:capsule_target_floor" size="0.054 0.066 0.0012" pos="0 0 0.0012" type="box" material="env:capsule_mat" rgba="1 1 1 1"/>
      <geom name="env:capsule_target_wall_north" size="0.054 0.0006 0.024" pos="0 0.066 0.012" type="box" material="env:capsule_mat" rgba="1 1 1 1"/>
      <geom name="env:capsule_target_wall_south" size="0.054 0.0006 0.024" pos="0 -0.066 0.012" type="box" material="env:capsule_mat" rgba="1 1 1 1"/>
      <geom name="env:capsule_target_wall_east" size="0.0006 0.066 0.024" pos="0.054 0 0.012" type="box" material="env:capsule_mat" rgba="1 1 1 1"/>
      <geom name="env:capsule_target_wall_west" size="0.0006 0.066 0.024" pos="-0.054 0 0.012" type="box" material="env:capsule_mat" rgba="1 1 1 1"/>
    </body>
    <body name="env:rectangle_target" pos="0.12 0.12 0.12">
      <joint name="env:rectangle_target_joint" type="free"/>
      <geom size="0.006 0.006 0.006" type="box" conaffinity="15" mass="0.01" rgba="0 0 0 0"/>
      <geom name="env:rectangle_target_geom" size="0.018 0.03 0.003" type="box" contype="0" conaffinity="0" rgba="0 0 0 0"/>
      <geom name="env:rectangle_target_floor" size="0.054 0.066 0.0012" pos="0 0 0.0012" type="box" material="env:rectangle_mat" rgba="1 1 1 1"/>
      <geom name="env:rectangle_target_wall_north" size="0.054 0.0006 0.024" pos="0 0.066 0.012" type="box" material="env:rectangle_mat" rgba="1 1 1 1"/>
      <geom name="env:rectangle_target_wall_south" size="0.054 0.0006 0.024" pos="0 -0.066 0.012" type="box" material="env:rectangle_mat" rgba="1 1 1 1"/>
      <geom name="env:rectangle_target_wall_east" size="0.0006 0.066 0.024" pos="0.054 0 0.012" type="box" material="env:rectangle_mat" rgba="1 1 1 1"/>
      <geom name="env:rectangle_target_wall_west" size="0.0006 0.066 0.024" pos="-0.054 0 0.012" type="box" material="env:rectangle_mat" rgba="1 1 1 1"/>
    </body>
    <body name="env:cube_obj" pos="-0.12 -0.12 0.504">
      <joint name="env:object0:joint" type="free"/>
      <geom name="env:object0_geom" size="0.018 0.018 0.018" type="box" contype="9" conaffinity="9" condim="4" friction="0.95 0.3 0.1" solref="0.001" solimp="0.999 0.999" mass="0.05" material="env:cube_mat" rgba="1 1 1 1"/>
      <site name="env:object0" pos="0 0 0" size="0.02" rgba="0 0 0 0"/>
    </body>
    <body name="env:cylinder_obj" pos="-0.12 0.12 0.504">
      <joint name="env:object1:joint" type="free"/>
      <geom name="env:object1_geom" size="0.018 0.024" type="cylinder" contype="9" conaffinity="9" condim="4" friction="0.95 0.3 0.1" solref="0.001" solimp="0.999 0.999" mass="0.05" material="env:cylinder_mat" rgba="1 1 1 1"/>
      <site name="env:object1" pos="0 0 0" size="0.02" rgba="0 0 0 0"/>
    </body>
    <body name="env:sphere_obj" pos="0.12 0 0.504">
      <joint name="env:object2:joint" type="free"/>
      <geom name="env:object2_geom" size="0.018" contype="9" conaffinity="9" condim="4" friction="0.95 0.3 0.1" solref="0.001" solimp="0.999 0.999" mass="0.05" material="env:sphere_mat" rgba="1 1 1 1"/>
      <site name="env:object2" pos="0 0 0" size="0.02" rgba="0 0 0 0"/>
    </body>
    <body name="env:capsule_obj" pos="0.12 -0.12 0.504" quat="0.707107 0.707107 0 0">
      <joint name="env:object3:joint" type="free"/>
      <geom name="env:object3_geom" size="0.015 0.018" type="capsule" contype="9" conaffinity="9" condim="4" friction="0.95 0.3 0.1" solref="0.001" solimp="0.999 0.999" mass="0.05" material="env:capsule_mat" rgba="1 1 1 1"/>
      <site name="env:object3" pos="0 0 0" size="0.02" rgba="0 0 0 0"/>
    </body>
    <body name="env:rectangle_obj" pos="0.12 0.12 0.504" quat="0.707107 0.707107 0 0">
      <joint name="env:object4:joint" type="free"/>
      <geom name="env:object4_geom" size="0.018 0.03 0.012" type="box" contype="9" conaffinity="9" condim="4" friction="0.95 0.3 0.1" solref="0.001" solimp="0.999 0.999" mass="0.05" material="env:rectangle_mat" rgba="1 1 1 1"/>
      <site name="env:object4" pos="0 0 0" size="0.02" rgba="0 0 0 0"/>
    </body>
    <body name="robot_0:base" childclass="robot_0:so101" pos="-0.2 0 0.5532">
      <inertial pos="0.0137179 -5.19711e-05 0.0334843" quat="0.420519 0.558762 0.57198 0.428704" mass="0.147" diaginertia="0.000136127 0.000131807 0.000113233"/>
      <geom class="robot_0:visual" pos="-0.00636471 -9.94414e-05 -0.0024" quat="0.5 0.5 0.5 0.5" material="robot_0:base_motor_holder_so101_v1_material" mesh="robot_0:base_motor_holder_so101_v1"/>
      <geom class="robot_0:visual" pos="-0.00636471 -8.97657e-09 -0.0024" quat="0.5 0.5 0.5 0.5" material="robot_0:base_so101_v2_material" mesh="robot_0:base_so101_v2"/>
      <geom class="robot_0:visual" pos="0.0263353 -8.97657e-09 0.0437" quat="1 0 0 0" material="robot_0:sts3215_03a_v1_material" mesh="robot_0:sts3215_03a_v1"/>
      <geom class="robot_0:visual" pos="-0.0309827 -0.000199441 0.0474" quat="0.5 0.5 0.5 0.5" material="robot_0:waveshare_mounting_plate_so101_v2_material" mesh="robot_0:waveshare_mounting_plate_so101_v2"/>
      <site name="robot_0:left_arm_center" pos="0 0 0" group="2" rgba="1 0.3 0.3 1"/>
      <site name="robot_0:baseframe" pos="0 0 0" quat="1 0 0 0" group="3"/>
      <camera name="robot_0:robotview" pos="1 0 0.2" quat="0.5 0.5 0.5 0.5"/>
      <body name="robot_0:shoulder" pos="0.0388353 -8.97657e-09 0.0624" quat="0 0 -1 0">
        <inertial pos="-0.0307604 -1.66727e-05 -0.0252713" quat="0.999865 0.00149563 0.0097084 0.0132043" mass="0.100006" diaginertia="8.37836e-05 8.10388e-05 2.39552e-05"/>
        <joint name="robot_0:shoulder_pan" class="robot_0:sts3215" pos="0 0 0" axis="0 0 1" range="-1.91986 1.91986"/>
        <geom class="robot_0:visual" pos="-0.0303992 0.000422241 -0.0417" quat="0.5 0.5 0.5 -0.5" material="robot_0:sts3215_03a_v1_material" mesh="robot_0:sts3215_03a_v1"/>
        <geom class="robot_0:collision" pos="-0.0303992 0.000422241 -0.0417" quat="0.5 0.5 0.5 -0.5" type="mesh" material="robot_0:sts3215_03a_v1_material" mesh="robot_0:sts3215_03a_v1"/>
        <geom class="robot_0:visual" pos="-0.0675992 -0.000177759 0.0158499" quat="0.5 0.5 -0.5 0.5" material="robot_0:motor_holder_so101_base_v1_material" mesh="robot_0:motor_holder_so101_base_v1"/>
        <geom class="robot_0:collision" pos="-0.0675992 -0.000177759 0.0158499" quat="0.5 0.5 -0.5 0.5" type="mesh" material="robot_0:motor_holder_so101_base_v1_material" mesh="robot_0:motor_holder_so101_base_v1"/>
        <geom class="robot_0:visual" pos="0.0122008 2.22413e-05 0.0464" quat="0.707107 -0.707107 0 0" material="robot_0:rotation_pitch_so101_v1_material" mesh="robot_0:rotation_pitch_so101_v1"/>
        <geom class="robot_0:collision" pos="0.0122008 2.22413e-05 0.0464" quat="0.707107 -0.707107 0 0" type="mesh" material="robot_0:rotation_pitch_so101_v1_material" mesh="robot_0:rotation_pitch_so101_v1"/>
        <body name="robot_0:upper_arm" pos="-0.0303992 -0.0182778 -0.0542" quat="0.5 -0.5 -0.5 -0.5">
          <inertial pos="-0.0898471 -0.00838224 0.0184089" quat="0.453195 0.454063 0.541891 0.542951" mass="0.103" diaginertia="0.000150873 0.000142487 3.72451e-05"/>
          <joint name="robot_0:shoulder_lift" class="robot_0:sts3215" pos="0 0 0" axis="0 0 1" range="-1.74533 1.74533"/>
          <geom class="robot_0:visual" pos="-0.11257 -0.0155 0.0187" quat="0 -0.707107 0.707107 0" material="robot_0:sts3215_03a_v1_material" mesh="robot_0:sts3215_03a_v1"/>
          <geom class="robot_0:collision" pos="-0.11257 -0.0155 0.0187" quat="0 -0.707107 0.707107 0" type="mesh" material="robot_0:sts3215_03a_v1_material" mesh="robot_0:sts3215_03a_v1"/>
          <geom class="robot_0:visual" pos="-0.065085 0.012 0.0182" quat="0 1 0 0" material="robot_0:upper_arm_so101_v1_material" mesh="robot_0:upper_arm_so101_v1"/>
          <geom class="robot_0:collision" pos="-0.065085 0.012 0.0182" quat="0 1 0 0" type="mesh" material="robot_0:upper_arm_so101_v1_material" mesh="robot_0:upper_arm_so101_v1"/>
          <body name="robot_0:lower_arm" pos="-0.11257 -0.028 0" quat="0.707107 0 0 0.707107">
            <inertial pos="-0.0980701 0.00324376 0.0182831" quat="0.510729 0.517006 0.487966 0.483477" mass="0.104" diaginertia="0.000160262 0.000145304 2.83125e-05"/>
            <joint name="robot_0:elbow_flex" class="robot_0:sts3215" pos="0 0 0" axis="0 0 1" range="-1.69 1.69"/>
            <geom class="robot_0:visual" pos="-0.0648499 -0.032 0.0182" quat="0 1 0 0" material="robot_0:under_arm_so101_v1_material" mesh="robot_0:under_arm_so101_v1"/>
            <geom class="robot_0:collision" pos="-0.0648499 -0.032 0.0182" quat="0 1 0 0" type="mesh" material="robot_0:under_arm_so101_v1_material" mesh="robot_0:under_arm_so101_v1"/>
            <geom class="robot_0:visual" pos="-0.0648499 -0.032 0.018" quat="0 -1 0 0" material="robot_0:motor_holder_so101_wrist_v1_material" mesh="robot_0:motor_holder_so101_wrist_v1"/>
            <geom class="robot_0:collision" pos="-0.0648499 -0.032 0.018" quat="0 -1 0 0" type="mesh" material="robot_0:motor_holder_so101_wrist_v1_material" mesh="robot_0:motor_holder_so101_wrist_v1"/>
            <geom class="robot_0:visual" pos="-0.1224 0.0052 0.0187" quat="0 0 1 0" material="robot_0:sts3215_03a_v1_material" mesh="robot_0:sts3215_03a_v1"/>
            <geom class="robot_0:collision" pos="-0.1224 0.0052 0.0187" quat="0 0 1 0" type="mesh" material="robot_0:sts3215_03a_v1_material" mesh="robot_0:sts3215_03a_v1"/>
            <body name="robot_0:wrist" pos="-0.1349 0.0052 0" quat="0.707107 0 0 -0.707107">
              <inertial pos="-0.000103312 -0.0386143 0.0281156" quat="0.967143 0.254226 0.00162226 -0.000146307" mass="0.079" diaginertia="3.68265e-05 2.74474e-05 1.89434e-05"/>
              <joint name="robot_0:wrist_flex" class="robot_0:sts3215" pos="0 0 0" axis="0 0 1" range="-1.65806 1.65806"/>
              <geom class="robot_0:visual" pos="0 -0.0424 0.0306" quat="0.5 0.5 0.5 -0.5" material="robot_0:sts3215_03a_no_horn_v1_material" mesh="robot_0:sts3215_03a_no_horn_v1"/>
              <geom class="robot_0:collision" pos="0 -0.0424 0.0306" quat="0.5 0.5 0.5 -0.5" type="mesh" material="robot_0:sts3215_03a_no_horn_v1_material" mesh="robot_0:sts3215_03a_no_horn_v1"/>
              <geom class="robot_0:visual" pos="0 -0.028 0.0181" quat="0.5 -0.5 -0.5 -0.5" material="robot_0:wrist_roll_pitch_so101_v2_material" mesh="robot_0:wrist_roll_pitch_so101_v2"/>
              <geom class="robot_0:collision" pos="0 -0.028 0.0181" quat="0.5 -0.5 -0.5 -0.5" type="mesh" material="robot_0:wrist_roll_pitch_so101_v2_material" mesh="robot_0:wrist_roll_pitch_so101_v2"/>
              <body name="robot_0:gripper" pos="0 -0.0611 0.0181" quat="0.0172091 -0.0172091 0.706897 0.706897">
                <inertial pos="0.000213627 0.000245138 -0.025187" quat="0.600717 0.355993 0.35863 0.61951" mass="0.087" diaginertia="4.33735e-05 3.77229e-05 2.42839e-05"/>
                <joint name="robot_0:wrist_roll" class="robot_0:sts3215" pos="0 0 0" axis="0 0 1" range="-2.74385 2.84121"/>
                <geom class="robot_0:visual" pos="0.0077 0.0001 -0.0234" quat="0.707107 -0.707107 0 0" material="robot_0:sts3215_03a_v1_material" mesh="robot_0:sts3215_03a_v1"/>
                <geom class="robot_0:collision" pos="0.0077 0.0001 -0.0234" quat="0.707107 -0.707107 0 0" type="mesh" material="robot_0:sts3215_03a_v1_material" mesh="robot_0:sts3215_03a_v1"/>
                <geom class="robot_0:visual" pos="0 -0.000218214 0.000949706" quat="0 1 0 0" material="robot_0:wrist_roll_follower_so101_v1_material" mesh="robot_0:wrist_roll_follower_so101_v1"/>
                <site name="robot_0:gripperframe" pos="-0.0079 -0.000218121 -0.0981274" quat="0.707107 0 0.707107 0" group="3"/>
                <camera name="robot_0:eye_in_hand" pos="0.15 0 0"/>
                <body name="robot_0:wrist_roll_follower_so101_v1" pos="0 -0.000218214 0.000949706" quat="0 1 0 0">
                  <geom name="robot_0:l_fingerpad1" class="robot_0:pad" size="0.0006 0.009 0.009" pos="-0.0127 -3.8e-05 0.05597"/>
                  <geom name="robot_0:l_fingerpad2" class="robot_0:pad" size="0.0006 0.007 0.009" pos="-0.011 -0.000179 0.075289"/>
                  <geom name="robot_0:l_fingerpad3" class="robot_0:pad" size="0.0006 0.005 0.005" pos="-0.009151 -0.000323 0.090101"/>
                  <geom name="robot_0:l_fingerpad4" class="robot_0:pad" size="0.0006 0.0035 0.003" pos="-0.007603 -0.000144 0.098972"/>
                </body>
                <body name="robot_0:moving_jaw_so101_v1" pos="0.0202 0.0188 -0.0234" quat="0.707107 0.707107 -1.85362e-08 1.85362e-08">
                  <inertial pos="-0.00157495 -0.0300244 0.0192755" quat="0.695265 0.717965 -0.0245618 -0.0230097" mass="0.012" diaginertia="6.63582e-06 5.29092e-06 1.86523e-06"/>
                  <joint name="robot_0:gripper" class="robot_0:sts3215" pos="0 0 0" axis="0 0 1" range="-0.174533 1.74533"/>
                  <geom class="robot_0:visual" pos="0 0 0.0189" quat="1 0 0 0" material="robot_0:moving_jaw_so101_v1_material" mesh="robot_0:moving_jaw_so101_v1"/>
                  <body name="robot_0:moving_jaw_so101_v1_pads" pos="0 0 0.0189" quat="1 0 0 0">
                    <geom name="robot_0:r_fingerpad1" class="robot_0:pad" size="0.0006 0.02 0.0075" pos="-0.00912 -0.042074 0.000135"/>
                    <geom name="robot_0:r_fingerpad2" class="robot_0:pad" size="0.0006 0.005 0.005" pos="-0.010802 -0.067138 0.000148"/>
                    <geom name="robot_0:r_fingerpad3" class="robot_0:pad" size="0.0006 0.0035 0.003" pos="-0.0126 -0.076 0.000135"/>
                  </body>
                </body>
              </body>
            </body>
          </body>
        </body>
      </body>
    </body>
    <body name="mount_0:base_r" pos="-0.2 0 0.5532">
      <body name="mount_0:controller_box">
        <inertial pos="-0.195 0 -0.228" mass="46.64" diaginertia="1.71363 1.27988 0.809981"/>
        <geom name="mount_0:controller_box_col" size="0.066 0.12 0.159" pos="-0.195 0 -0.228" type="box" group="3"/>
      </body>
      <body name="mount_0:pedestal_feet">
        <inertial pos="-0.0735 0 -0.4548" mass="167.09" diaginertia="8.16095 9.59375 15.0785"/>
        <geom name="mount_0:pedestal_feet_col" size="0.231 0.21 0.093" pos="-0.0735 0 -0.4548" type="box" group="3"/>
      </body>
      <body name="mount_0:torso">
        <inertial pos="0 0 0" mass="0.0001" diaginertia="1e-08 1e-08 1e-08"/>
        <geom name="mount_0:torso_vis" size="0.03 0.03 0.03" pos="0 0 -0.03" type="box" contype="0" conaffinity="0" group="1" rgba="0.2 0.2 0.2 1"/>
      </body>
      <body name="mount_0:pedestal">
        <inertial pos="0 0 0" quat="0.659267 -0.259505 -0.260945 0.655692" mass="60.864" diaginertia="6.0869 5.81635 4.20915"/>
        <geom name="mount_0:pedestal_vis" type="mesh" contype="0" conaffinity="0" group="1" rgba="0.2 0.2 0.2 1" mesh="mount_0:pedestal"/>
        <geom name="mount_0:pedestal_col" size="0.108 0.186" pos="-0.012 0 -0.174" type="cylinder" group="3" rgba="0.2 0.2 0.2 1"/>
      </body>
    </body>
  </worldbody>

  <actuator>
    <general name="robot_0:shoulder_pan" joint="robot_0:shoulder_pan" ctrllimited="true" ctrlrange="-3.35 3.35" forcerange="-3.35 3.35"/>
    <general name="robot_0:shoulder_lift" joint="robot_0:shoulder_lift" ctrllimited="true" ctrlrange="-3.35 3.35" forcerange="-3.35 3.35"/>
    <general name="robot_0:elbow_flex" joint="robot_0:elbow_flex" ctrllimited="true" ctrlrange="-3.35 3.35" forcerange="-3.35 3.35"/>
    <general name="robot_0:wrist_flex" joint="robot_0:wrist_flex" ctrllimited="true" ctrlrange="-3.35 3.35" forcerange="-3.35 3.35"/>
    <general name="robot_0:wrist_roll" joint="robot_0:wrist_roll" ctrllimited="true" ctrlrange="-3.35 3.35" forcerange="-3.35 3.35"/>
    <general name="robot_0:gripper" class="robot_0:sts3215" joint="robot_0:gripper" ctrlrange="-0.17453 1.74533" forcerange="-3.35 3.35"/>
  </actuator>
</mujoco>
